Workbook

Sheet insumos
B3: PRESUPUESTO Costo de Venta FEBRERO 24 | C3: SUMATORIA | E3: CANTIDADES
C4: mensual | D4: semanal | E4: semanal | F4: medida
B5: 5008 - CARNES Y PUERCO | C5: ='[1]resultado estimado'!$O$14 -> 4565.1796
B6: chuleta | C6: =[2]CHULETAS!$C$21 -> 1404.5338 | D6: =C6/4 -> 351.13345 | E6: =[2]CHULETAS!$C$18 -> 270.26898 | F6: u
B7: churrasco | C7: =[2]CHURRASCO!$C$21 -> 285.96554 | D7: =C7/4 -> 71.491386 | E7: =[2]CHURRASCO!$B$18 -> 18.953178 | F7: u
B8: costilla para parrilla | C8: ='[2]COSTILLAS ASADAS'!$C$21 -> 391.36152 | D8: =C8/4 -> 97.84038 | E8: =[2]CHULETAS!$F$18 -> 78.378003 | F8: kg
B9: filete de res | C9: ='[2]FILETE DE RES '!$C$21 -> 405.24574 | D9: =C9/4 -> 101.31143 | E9: ='[2]FILETE DE RES '!$E$20 -> 11.269348 | F9: kg
B10: rincon | D10: =C10/4 -> 0 | F10: kg
B11: lomo | C11: =[3]LOMO!$C$21 -> 236.51472 | D11: =C11/4 -> 59.12868 | E11: =[3]LOMO!$E$20 -> 9.09672 | F11: kg
B12: lengua | C12: =[3]LENGUA!$C$21 -> 184.98887 | D12: =C12/4 -> 46.247216 | E12: =[3]LENGUA!$E$20 -> 5.46012 | F12: kg
B13: costilla horno | C13: ='[3]COSTILLA HORNO'!$C$21 -> 390.35299 | D13: =C13/4 -> 97.588248 | E13: ='[3]COSTILLA HORNO'!$E$20 -> 15.03671 | F13: kg
B14: bistec picado | C14: ='[3]BISTEC PICADO'!$C$21 -> 253.56175 | D14: =C14/4 -> 63.390438 | E14: ='[3]BISTEC PICADO'!$E$20 -> 8.8042275 | F14: kg
B15: carne guisada | C15: ='[3]CARNE GUISADA'!$C$21 -> 155.53526 | D15: =C15/4 -> 38.883814 | E15: ='[3]CARNE GUISADA'!$E$20 -> 6.7624025 | F15: kg
B16: mondongo | C16: =[3]MONDONGO!$C$21 -> 47.804304 | D16: =C16/4 -> 11.951076 | E16: =[3]MONDONGO!$E$20 -> 4.979615 | F16: kg
B17: rabito | C17: =[4]resultado!N26 -> 0 | D17: =C17/4 -> 0 | F17: kg
B18: costilla desayuno | C18: ='[5]COSTILLA FRITA'!$C$21 -> 226.64542 | D18: =C18/4 -> 56.661355 | E18: ='[5]COSTILLA FRITA'!$E$20 -> 7.90256 | F18: kg
B19: higado | C19: =[5]HIGADO!$C$21 -> 78.967625 | D19: =C19/4 -> 19.741906 | E19: =[5]HIGADO!$F$20 -> 18.181818 | F19: kg
B20: bofe | C20: =[5]BOFE!$C$21 -> 193.70203 | D20: =C20/4 -> 48.425507 | E20: =[5]BOFE!$E$20 -> 13.34036 | F20: kg
B21: carnes adicionales | C21: ='[1]resultado estimado'!$N$25+'[1]resultado estimado'!$N$30+'[1]resultado estimado'!$N$32 -> 310 | D21: =C21/4 -> 77.5 | F21: kg
B23: 5009 - MARISCOS | C23: ='[1]resultado estimado'!$O$35 -> 635.81056
B24: filete de pescado | C24: ='[3]FILETE DE PESCADO'!$C$21 -> 283.16468 | D24: =C24/4 -> 70.791171 | E24: =('[3]COSTILLA HORNO'!$C$18)/4 -> 57.8335 | F24: u
B25: corvina | C25: =[3]CORVINA!$C$22 -> 75.132288 | D25: =C25/4 -> 18.783072 | E25: =[3]CORVINA!$E$21 -> 6.830208 | F25: lb
B26: bacalao | C26: =[3]BACALAO!$C$21 -> 127.51358 | D26: =C26/4 -> 31.878396 | E26: =[3]BACALAO!$E$20 -> 3.1284 | F26: kg
B28: 5010 - POLLO | C28: ='[1]resultado estimado'!$O$40 -> 4323.9313
B29: pollo | C29: ='[2]POLLO calculo'!$B$18 -> 4131.6058 | D29: =C29/4 -> 1032.9015 | E29: ='[2]POLLO calculo'!$B$14 -> 32.729569 | F29: bolsas
B30: filete de pechuga parrilla | C30: ='[2]FILETE DE PECHUGA'!$C$22 -> 90.540205 | D30: =C30/4 -> 22.635051 | E30: ='[2]FILETE DE PECHUGA'!$E$21 -> 10.778596 | F30: lb
B31: filete de pechuga criolla | C31: ='[3]FILETE PECHUGA '!$C$22 -> 101.78529 | D31: =C31/4 -> 25.446324 | E31: ='[3]FILETE PECHUGA '!$E$21 -> 12.117297 | F31: lb
B34: 5011 - VIVERES (MENESTRAS, KETCHUP, OTROS) | C34: ='[1]resultado estimado'!$O$45 -> 1564.0177
B35: porotos | C35: =[4]resultado!N42 -> 287.5 | D35: =C35/4 -> 71.875 | E35: =[2]ARROZ!$E$18 -> 48.803722 | F35: u
B36: lentejas | C36: =[4]resultado!N43 -> 222.75 | D36: =C36/4 -> 55.6875 | E36: =[2]ARROZ!$D$18 -> 81.627095 | F36: u
B37: chorizo de parrilla | C37: ='[2]chorizo parrilla '!$C$21 -> 134.16826 | D37: =C37/4 -> 33.542065 | E37: ='[2]chorizo parrilla '!$B$18 -> 49.430412 | F37: u
C38: =[4]resultado!N45 -> 0 | D38: =C38/4 -> 0
B39: almojabano | C39: =[5]ALMOJABANO!$C$20 -> 5.955 | D39: =C39/4 -> 1.48875 | E39: =[5]ALMOJABANO!$B$18 -> 11.91 | F39: u
B40: salchicha para guisar | C40: ='[5]SALCHICHA GUI'!$C$22 -> 51.02482 | D40: =C40/4 -> 12.756205 | E40: ='[5]SALCHICHA GUI'!$E$21 -> 9.111575 | F40: lb
B41: bollo | C41: =[5]BOLLO!$C$20 -> 157.642 | D41: =C41/4 -> 39.4105 | E41: =[5]BOLLO!$B$18 -> 78.821 | F41: u
B42: carimañola | C42: =[5]CARIMAÑOLA!$C$20 -> 60.78256 | D42: =C42/4 -> 15.19564 | E42: =[5]CARIMAÑOLA!$B$18 -> 36.616 | F42: u
B43: tortilla | C43: =[5]TORTILLA!$C$20 -> 52.40274 | D43: =C43/4 -> 13.100685 | E43: =[5]TORTILLA!$B$19 -> 10.07745 | F43: paq
B44: empa | C44: ='[5]EMP DE MAIZ'!$C$20 -> 41.792314 | D44: =C44/4 -> 10.448079 | E44: ='[5]EMP DE MAIZ'!$B$19 -> 6.1459286 | F44: paq
B45: otros viveres | C45: ='[1]resultado estimado'!$N$56 -> 550 | D45: =C45/4 -> 137.5
B48: 5012 - SODAS, REFRESCOS AGUA | C48: ='[1]resultado estimado'!$O$58 -> 2526.2253
...

Sheet lista para compra
B3: PRESUPUESTO Costo de Venta FEBRERO 24 | C3: SUMATORIA | D3: SUMATORIA | F3: CANTIDADES | H3: CANTIDADES STOCK
C4: mensual | D4: mensual | E4: semanal | F4: semanal | G4: medida | H4: semanal | I4: comprar
B5: 5008 - CARNES Y PUERCO | C5: =SUM(C6:C20) -> 3707.101 | D5: =insumos!C5:C65 -> 4565.1796
B6: chuleta | C6: =[6]CHULETAS!$C$21 -> 947.41347 | D6: =insumos!C6:C66 -> 1404.5338 | E6: =D6/4 -> 351.13345 | F6: =insumos!E6 -> 270.26898 | G6: u | H6: 265 | I6: =F6-H6 -> 5.2689764 | J6: *
B7: churrasco | C7: =[6]CHURRASCO!$C$20 -> 400.19216 | D7: =insumos!C7:C67 -> 285.96554 | E7: =D7/4 -> 71.491386 | F7: =insumos!E7 -> 18.953178 | G7: u | H7: 29 | I7: =H7-F7 -> 10.046822 | J7: cuando se acaba
B8: costilla para parrilla + | C8: ='[6]COSTILLAS ASADAS'!$C$21 -> 309.17719 | D8: =insumos!C8:C68 -> 391.36152 | E8: =D8/4 -> 97.84038 | F8: =insumos!E8 -> 78.378003 | G8: kg | I8: =F8-H8 -> 78.378003 | J8: mierco
B9: filete de res | C9: ='[6]FILETE DE RES '!$C$21 -> 67.766018 | D9: =insumos!C9:C69 -> 405.24574 | E9: =D9/4 -> 101.31143 | F9: =insumos!E9 -> 11.269348 | G9: kg | I9: =F9-H9 -> 11.269348 | J9: *
B10: rincon | C10: =[6]RINCON!$C$21 -> 160.32132 | D10: =insumos!C10:C70 -> 0 | E10: =D10/4 -> 0 | F10: =insumos!E10 -> 0 | G10: kg | I10: =F10-H10 -> 0
B11: lomo | C11: =[7]LOMO!$C$21 -> 175.29174 | D11: =insumos!C11:C71 -> 236.51472 | E11: =D11/4 -> 59.12868 | F11: =insumos!E11 -> 9.09672 | G11: kg | I11: =F11-H11 -> 9.09672 | J11: *
B12: lengua | C12: =[7]LENGUA!$C$21 -> 210.6419 | D12: =insumos!C12:C72 -> 184.98887 | E12: =D12/4 -> 46.247216 | F12: =insumos!E12 -> 5.46012 | G12: kg | J12: no hay
B13: costilla horno | C13: ='[7]COSTILLA HORNO'!$C$21 -> 658.25916 | D13: =insumos!C13:C73 -> 390.35299 | E13: =D13/4 -> 97.588248 | F13: =insumos!E13 -> 15.03671 | G13: kg | I13: =F13-H13 -> 15.03671
B14: bistec picado | C14: ='[7]BISTEC PICADO'!$C$21 -> 227.77807 | D14: =insumos!C14:C74 -> 253.56175 | E14: =D14/4 -> 63.390438 | F14: =insumos!E14 -> 8.8042275 | G14: kg | I14: =F14-H14 -> 8.8042275 | J14: *
B15: carne guisada | C15: ='[7]CARNE GUISADA'!$C$21 -> 111.69697 | D15: =insumos!C15:C75 -> 155.53526 | E15: =D15/4 -> 38.883814 | F15: =insumos!E15 -> 6.7624025 | G15: kg | I15: =F15-H15 -> 6.7624025 | J15: *
B16: mondongo | C16: =[7]MONDONGO!$C$21 -> 52.612893 | D16: =insumos!C16:C76 -> 47.804304 | E16: =D16/4 -> 11.951076 | F16: =insumos!E16 -> 4.979615 | G16: kg | I16: =F16-H16 -> 4.979615 | J16: *
B17: rabito | C17: ='[7]GUACHO DE RABITO'!$C$22 -> 150.62298 | D17: =insumos!C17:C77 -> 0 | E17: =D17/4 -> 0 | F17: =insumos!E17 -> 0 | G17: kg | I17: =F17-H17 -> 0
B18: costilla desayuno + | C18: ='[8]COSTILLA FRITA'!$C$21 -> 81.7098 | D18: =insumos!C18:C78 -> 226.64542 | E18: =D18/4 -> 56.661355 | F18: =insumos!E18 -> 7.90256 | G18: kg | I18: =F18-H18 -> 7.90256
B19: higado | C19: =[8]HIGADO!$C$21 -> 54.76185 | D19: =insumos!C19:C79 -> 78.967625 | E19: =D19/4 -> 19.741906 | F19: =insumos!E19 -> 18.181818 | G19: kg | I19: =F19-H19 -> 18.181818
B20: bofe | C20: =[8]BOFE!$C$21 -> 98.8555 | D20: =insumos!C20:C80 -> 193.70203 | E20: =D20/4 -> 48.425507 | F20: =insumos!E20 -> 13.34036 | G20: kg | I20: =F20-H20 -> 13.34036
B21: carnes adicionales | D21: =insumos!C21:C81 -> 310 | E21: =D21/4 -> 77.5 | F21: =insumos!E21 -> 0 | G21: kg | I21: =F21-H21 -> 0 | J21: *
B23: 5009 - MARISCOS | C23: =SUM(C24:C26) -> 333.25043 | D23: =insumos!C23:C82 -> 635.81056
B24: filete de pescado | C24: ='[7]FILETE DE PESCADO'!$C$21 -> 207.06273 | D24: =insumos!C24:C83 -> 283.16468 | E24: =D24/4 -> 70.791171 | F24: =insumos!E24 -> 57.8335 | G24: u | I24: =F24-H24 -> 57.8335 | J24: *
B25: corvina | C25: =[7]CORVINA!$C$22 -> 57.407724 | D25: =insumos!C25:C84 -> 75.132288 | E25: =D25/4 -> 18.783072 | F25: =insumos!E25 -> 6.830208 | G25: lb | I25: =F25-H25 -> 6.830208
B26: bacalao | C26: =[7]BACALAO!$C$21 -> 68.779973 | D26: =insumos!C26:C85 -> 127.51358 | E26: =D26/4 -> 31.878396 | F26: =insumos!E26 -> 3.1284 | G26: kg | I26: =F26-H26 -> 3.1284
B28: 5010 - POLLO | C28: =SUM(C29:C31) -> 4187.8106 | D28: =insumos!C28:C87 -> 4323.9313
B29: pollo | C29: ='[6]POLLO calculo'!$B$17 -> 3915.91 | D29: =insumos!C29:C88 -> 4131.6058 | E29: =D29/4 -> 1032.9015 | F29: =insumos!E29 -> 32.729569 | G29: bolsas | I29: =F29-H29 -> 32.729569 | J29: *
B30: filete de pechuga parrilla | C30: ='[6]FILETE DE PECHUGA'!$C$22 -> 82.883895 | D30: =insumos!C30:C89 -> 90.540205 | E30: =D30/4 -> 22.635051 | F30: =insumos!E30 -> 10.778596 | G30: lb | I30: =F30-H30 -> 10.778596 | J30: *
B31: filete de pechuga criolla | C31: ='[7]FILETE PECHUGA '!$C$22 -> 189.01671 | D31: =insumos!C31:C90 -> 101.78529 | E31: =D31/4 -> 25.446324 | F31: =insumos!E31 -> 12.117297 | G31: lb | I31: =F31-H31 -> 12.117297 | J31: *
B34: 5011 - VIVERES (MENESTRAS, KETCHUP, OTROS) | C34: =SUM(C35:C44)+1194 -> 2172.0411 | D34: =insumos!C34:C93 -> 1564.0177
B35: porotos | C35: =[6]ARROZ!$E$21 -> 276 | D35: =insumos!C35:C94 -> 287.5 | E35: =D35/4 -> 71.875 | F35: =insumos!E35 -> 48.803722 | G35: u | J35: *
B36: lentejas | C36: =[6]ARROZ!$D$21 -> 198.72 | D36: =insumos!C36:C95 -> 222.75 | E36: =D36/4 -> 55.6875 | F36: =insumos!E36 -> 81.627095 | G36: u | J36: *
B37: chorizo de parrilla | C37: ='[6]chorizo parrilla '!$C$21 -> 105.48208 | D37: =insumos!C37:C96 -> 134.16826 | E37: =D37/4 -> 33.542065 | F37: =insumos!E37 -> 49.430412 | G37: u | J37: *
B38: chorizo tableño | C38: ='[8]CHORIZO TABLEÑO'!$C$20 -> 15.18 | D38: =insumos!C38:C97 -> 0 | E38: =D38/4 -> 0 | J38: *
B39: almojabano | C39: =[8]ALMOJABANO!$C$20 -> 16.192 | D39: =insumos!C39:C98 -> 5.955 | E39: =D39/4 -> 1.48875 | J39: *
B40: salchicha para guisar | C40: ='[8]SALCHICHA GUI'!$C$22 -> 187.0407 | D40: =insumos!C40:C99 -> 51.02482 | E40: =D40/4 -> 12.756205 | F40: =insumos!E40 -> 9.111575 | G40: lb
B41: bollo | C41: =[8]BOLLO!$C$20 -> 86.043 | D41: =insumos!C41:C100 -> 157.642 | E41: =D41/4 -> 39.4105 | F41: =insumos!E41 -> 78.821 | G41: u
B42: carimañola | C42: =[8]CARIMAÑOLA!$C$20 -> 49.495632 | D42: =insumos!C42:C101 -> 60.78256 | E42: =D42/4 -> 15.19564 | F42: =insumos!E42 -> 36.616 | G42: u
B43: tortilla | C43: =[8]TORTILLA!$C$20 -> 24.49408 | D43: =insumos!C43:C102 -> 52.40274 | E43: =D43/4 -> 13.100685 | F43: =insumos!E43 -> 10.07745 | G43: paq
B44: empa | C44: ='[8]EMP DE MAIZ'!$C$20 -> 19.3936 | D44: =insumos!C44:C103 -> 41.792314 | E44: =D44/4 -> 10.448079 | F44: =insumos!E44 -> 6.1459286 | G44: paq
B58: 5012 - SODAS, REFRESCOS AGUA | C58: =C59+300 -> 2375.2467 | D58: =insumos!C48 -> 2526.2253
B59: sodas | C59: =[6]SODAS!$B$21 -> 2075.2467 | D59: =insumos!C49 -> 1826.2253 | E59: =insumos!D49 -> 456.55632 | F59: =insumos!E49 -> 62.973286 | G59: cajas | H59: 11 | I59: =F59-H59 -> 51.973286 | J59: *
...

Sheet control de compras
B3: PRESUPUESTO Costo de Venta ENERO 24 | C3: SUMATORIA
C4: mensual | D4: semanal | E4: semana 1 | F4: semana 2 | G4: semana 3 | H4: semana 4 | I4: sumat sem | J4: RES TOTAL mens
B5: 5008 - CARNES Y PUERCO | C5: =insumos!C5 -> 4565.1796 | J5: =(C5-I5)-SUM(I5:I20) -> 3647.2796
B6: chuleta | C6: =insumos!C6 -> 1404.5338 | D6: =C6/4 -> 351.13345 | E6: ='sem 1'!Q7 -> 0 | F6: ='sem2'!Q7 -> 249.09 | G6: ='sem3'!Q7 -> 0 | H6: ='sem4'!Q7 -> 0 | I6: =E6+F6+G6+H6 -> 249.09 | J6: =C6-I6 -> 1155.4438
B7: churrasco | C7: =insumos!C7 -> 285.96554 | D7: =C7/4 -> 71.491386 | E7: ='sem 1'!Q8 -> 0 | F7: ='sem2'!Q8 -> 0 | G7: ='sem3'!Q8 -> 0 | H7: ='sem4'!Q8 -> 0 | I7: =E7+F7+G7+H7 -> 0 | J7: =C7-I7 -> 285.96554
B8: costilla para parrilla | C8: =insumos!C8 -> 391.36152 | D8: =C8/4 -> 97.84038 | E8: ='sem 1'!Q9 -> 137.91 | F8: ='sem2'!Q9 -> 0 | G8: ='sem3'!Q9 -> 0 | H8: ='sem4'!Q9 -> 0 | I8: =E8+F8+G8+H8 -> 137.91 | J8: =C8-I8 -> 253.45152
B9: filete de res | C9: =insumos!C9 -> 405.24574 | D9: =C9/4 -> 101.31143 | E9: ='sem 1'!Q10 -> 93.71 | F9: ='sem2'!Q10 -> 24.32 | G9: ='sem3'!Q10 -> 0 | H9: ='sem4'!Q10 -> 0 | I9: =E9+F9+G9+H9 -> 118.03 | J9: =C9-I9 -> 287.21574
B10: rincon | C10: =insumos!C10 -> 0 | D10: =C10/4 -> 0 | E10: ='sem 1'!Q11 -> 0 | F10: ='sem2'!Q11 -> 0 | G10: ='sem3'!Q11 -> 0 | H10: ='sem4'!Q11 -> 0 | I10: =E10+F10+G10+H10 -> 0 | J10: =C10-I10 -> 0
B11: lomo | C11: =insumos!C11 -> 236.51472 | D11: =C11/4 -> 59.12868 | E11: ='sem 1'!Q12 -> 53.3 | F11: ='sem2'!Q12 -> 0 | G11: ='sem3'!Q12 -> 0 | H11: ='sem4'!Q12 -> 0 | I11: =E11+F11+G11+H11 -> 53.3 | J11: =C11-I11 -> 183.21472
B12: lengua | C12: =insumos!C12 -> 184.98887 | D12: =C12/4 -> 46.247216 | E12: ='sem 1'!Q13 -> 0 | F12: ='sem2'!Q13 -> 0 | G12: ='sem3'!Q13 -> 0 | H12: ='sem4'!Q13 -> 0 | I12: =E12+F12+G12+H12 -> 0 | J12: =C12-I12 -> 184.98887
B13: costilla horno | C13: =insumos!C13 -> 390.35299 | D13: =C13/4 -> 97.588248 | E13: ='sem 1'!Q14 -> 137.91 | F13: ='sem2'!Q14 -> 0 | G13: ='sem3'!Q14 -> 0 | H13: ='sem4'!Q14 -> 0 | I13: =E13+F13+G13+H13 -> 137.91 | J13: =C13-I13 -> 252.44299
B14: bistec picado | C14: =insumos!C14 -> 253.56175 | D14: =C14/4 -> 63.390438 | E14: ='sem 1'!Q15 -> 48.17 | F14: ='sem2'!Q15 -> 0 | G14: ='sem3'!Q15 -> 0 | H14: ='sem4'!Q15 -> 0 | I14: =E14+F14+G14+H14 -> 48.17 | J14: =C14-I14 -> 205.39175
B15: carne guisada | C15: =insumos!C15 -> 155.53526 | D15: =C15/4 -> 38.883814 | E15: ='sem 1'!Q16 -> 35.88 | F15: ='sem2'!Q16 -> 0 | G15: ='sem3'!Q16 -> 0 | H15: ='sem4'!Q16 -> 0 | I15: =E15+F15+G15+H15 -> 35.88 | J15: =C15-I15 -> 119.65526
B16: mondongo | C16: =insumos!C16 -> 47.804304 | D16: =C16/4 -> 11.951076 | E16: ='sem 1'!Q17 -> 9.6 | F16: ='sem2'!Q17 -> 0 | G16: ='sem3'!Q17 -> 0 | H16: ='sem4'!Q17 -> 0 | I16: =E16+F16+G16+H16 -> 9.6 | J16: =C16-I16 -> 38.204304
B17: rabito | C17: =insumos!C17 -> 0 | D17: =C17/4 -> 0 | E17: ='sem 1'!Q18 -> 0 | F17: ='sem2'!Q18 -> 0 | G17: ='sem3'!Q18 -> 0 | H17: ='sem4'!Q18 -> 0 | I17: =E17+F17+G17+H17 -> 0 | J17: =C17-I17 -> 0
... B21: carnes adicionales | C21: =insumos!C21 -> 310 | D21: =C21/4 -> 77.5 | E21: ='sem 1'!Q22 -> 46.98 | F21: ='sem2'!Q22 -> 0 | G21: ='sem3'!Q22 -> 0 | H21: ='sem4'!Q22 -> 0 | I21: =E21+F21+G21+H21 -> 46.98 | J21: =C21-I21 -> 263.02
I22: =E22+F22+G22+H22 -> 0
B23: 5009 - MARISCOS | C23: =insumos!C23 -> 635.81056 | I23: =E23+F23+G23+H23 -> 0 | J23: =(C23-I23)-SUM(I23:I26) -> 569.81056
B24: filete de pescado | C24: =insumos!C24 -> 283.16468 | D24: =C24/4 -> 70.791171 | E24: ='sem 1'!Q27 -> 66 | F24: ='sem2'!Q27 -> 0 | G24: ='sem3'!Q27 -> 0 | H24: ='sem4'!Q27 -> 0 | I24: =E24+F24+G24+H24 -> 66 | J24: =C24-I24 -> 217.16468
B25: corvina | C25: =insumos!C25 -> 75.132288 | D25: =C25/4 -> 18.783072 | E25: ='sem 1'!Q28 -> 0 | F25: ='sem2'!Q28 -> 0 | G25: ='sem3'!Q28 -> 0 | H25: ='sem4'!Q28 -> 0 | I25: =E25+F25+G25+H25 -> 0 | J25: =C25-I25 -> 75.132288
B26: bacalao | C26: =insumos!C26 -> 127.51358 | D26: =C26/4 -> 31.878396 | E26: ='sem 1'!Q29 -> 0 | F26: ='sem2'!Q29 -> 0 | G26: ='sem3'!Q29 -> 0 | H26: ='sem4'!Q29 -> 0 | I26: =E26+F26+G26+H26 -> 0 | J26: =C26-I26 -> 127.51358
B27: otros | I27: =E27+F27+G27+H27 -> 0
I28: =E28+F28+G28+H28 -> 0
B29: 5010 - POLLO | C29: =insumos!C28 -> 4323.9313 | I29: =E29+F29+G29+H29 -> 0 | J29: =(C29-I29)-SUM(I30:I32) -> 3311.3813
B30: pollo | C30: =insumos!C29 -> 4131.6058 | D30: =C30/4 -> 1032.9015 | E30: ='sem 1'!Q33 -> 928.55 | F30: ='sem2'!Q33 -> 0 | G30: ='sem3'!Q33 -> 0 | H30: ='sem4'!Q33 -> 0 | I30: =E30+F30+G30+H30 -> 928.55 | J30: =C30-I30 -> 3203.0558
B31: filete de pechuga parrilla | C31: =insumos!C30 -> 90.540205 | D31: =C31/4 -> 22.635051 | E31: ='sem 1'!Q34 -> 42 | F31: ='sem2'!Q34 -> 0 | G31: ='sem3'!Q34 -> 0 | H31: ='sem4'!Q34 -> 0 | I31: =E31+F31+G31+H31 -> 42 | J31: =C31-I31 -> 48.540205
B32: filete de pechuga criolla | C32: =insumos!C31 -> 101.78529 | D32: =C32/4 -> 25.446324 | E32: ='sem 1'!Q35 -> 42 | F32: ='sem2'!Q35 -> 0 | G32: ='sem3'!Q35 -> 0 | H32: ='sem4'!Q35 -> 0 | I32: =E32+F32+G32+H32 -> 42 | J32: =C32-I32 -> 59.785295
I33: =E33+F33+G33+H33 -> 0
B34: 5011 - VIVERES (MENESTRAS, KETCHUP, OTROS) | C34: =insumos!C34 -> 1564.0177 | I34: =E34+F34+G34+H34 -> 0 | J34: =(C34-I34)-SUM(I35:I45) -> 1127.3177
B35: porotos | C35: =insumos!C35 -> 287.5 | D35: =C35/4 -> 71.875 | E35: ='sem 1'!Q38 -> 70 | F35: ='sem2'!Q38 -> 0 | G35: ='sem3'!Q38 -> 0 | H35: ='sem4'!Q38 -> 0 | I35: =E35+F35+G35+H35 -> 70 | J35: =C35-I35 -> 217.5
B36: lentejas | C36: =insumos!C36 -> 222.75 | D36: =C36/4 -> 55.6875 | E36: ='sem 1'!Q39 -> 25 | F36: ='sem2'!Q39 -> 0 | G36: ='sem3'!Q39 -> 0 | H36: ='sem4'!Q39 -> 0 | I36: =E36+F36+G36+H36 -> 25 | J36: =C36-I36 -> 197.75
B37: chorizo de parrilla | C37: =insumos!C37 -> 134.16826 | D37: =C37/4 -> 33.542065 | E37: ='sem 1'!Q40 -> 36.16 | F37: ='sem2'!Q40 -> 21.45 | G37: ='sem3'!Q40 -> 0 | H37: ='sem4'!Q40 -> 0 | I37: =E37+F37+G37+H37 -> 57.61 | J37: =C37-I37 -> 76.558261
B38: chorizo tableño | C38: =insumos!C38 -> 0 | D38: =C38/4 -> 0 | E38: ='sem 1'!Q41 -> 0 | F38: ='sem2'!Q41 -> 0 | G38: ='sem3'!Q41 -> 0 | H38: ='sem4'!Q41 -> 0 | I38: =E38+F38+G38+H38 -> 0 | J38: =C38-I38 -> 0
B39: almojabano | C39: =insumos!C39 -> 5.955 | D39: =C39/4 -> 1.48875 | E39: ='sem 1'!Q42 -> 0 | F39: ='sem2'!Q42 -> 0 | G39: ='sem3'!Q42 -> 0 | H39: ='sem4'!Q42 -> 0 | I39: =E39+F39+G39+H39 -> 0 | J39: =C39-I39 -> 5.955
B40: salchicha para guisar | C40: =insumos!C40 -> 51.02482 | D40: =C40/4 -> 12.756205 | E40: ='sem 1'!Q43 -> 28 | F40: ='sem2'!Q43 -> 55 | G40: ='sem3'!Q43 -> 0 | H40: ='sem4'!Q43 -> 0 | I40: =E40+F40+G40+H40 -> 83 | J40: =C40-I40 -> -31.97518
B41: bollo | C41: =insumos!C41 -> 157.642 | D41: =C41/4 -> 39.4105 | E41: ='sem 1'!Q44 -> 25 | F41: ='sem2'!Q44 -> 0 | G41: ='sem3'!Q44 -> 0 | H41: ='sem4'!Q44 -> 0 | I41: =E41+F41+G41+H41 -> 25 | J41: =C41-I41 -> 132.642
B42: carimañola | C42: =insumos!C42 -> 60.78256 | D42: =C42/4 -> 15.19564 | E42: ='sem 1'!Q45 -> 0 | F42: ='sem2'!Q45 -> 8.5 | G42: ='sem3'!Q45 -> 0 | H42: ='sem4'!Q45 -> 0 | I42: =E42+F42+G42+H42 -> 8.5 | J42: =C42-I42 -> 52.28256
B43: tortilla | C43: =insumos!C43 -> 52.40274 | D43: =C43/4 -> 13.100685 | E43: ='sem 1'!Q46 -> 17.77 | F43: ='sem2'!Q46 -> 0 | G43: ='sem3'!Q46 -> 0 | H43: ='sem4'!Q46 -> 0 | I43: =E43+F43+G43+H43 -> 17.77 | J43: =C43-I43 -> 34.63274
B44: empa | C44: =insumos!C44 -> 41.792314 | D44: =C44/4 -> 10.448079 | E44: ='sem 1'!Q47 -> 2.95 | F44: ='sem2'!Q47 -> 0 | G44: ='sem3'!Q47 -> 0 | H44: ='sem4'!Q47 -> 0 | I44: =E44+F44+G44+H44 -> 2.95 | J44: =C44-I44 -> 38.842314
B45: otros viveres | C45: =insumos!C45 -> 550 | D45: =C45/4 -> 137.5 | E45: ='sem 1'!Q48 -> 146.87 | F45: ='sem2'!Q48 -> 0 | G45: ='sem3'!Q48 -> 0 | H45: ='sem4'!Q48 -> 0 | I45: =E45+F45+G45+H45 -> 146.87 | J45: =C45-I45 -> 403.13
...

Sheet sem 1
A3: PRESUPUESTO Costo de Venta DIC 23
B4: cheque | C4: cheque | D4: cheque | E4: cheque | F4: cheque | G4: cheque | H4: cheque | J4: contado | K4: contado | L4: contado | M4: contado | N4: contado | O4: contado | P4: contado
B5: 45597 | C5: 45598 | D5: 45599 | E5: 45600 | F5: 45601 | G5: 45602 | H5: 45603 | J5: 45597 | K5: 45598 | L5: 45599 | M5: 45600 | N5: 45601 | O5: 45602 | P5: 45603 | Q5: TOTAL
A6: 5008 - CARNES Y PUERCO
A7: chuleta | Q7: =SUM(B7:P7) -> 0
A8: churrasco | Q8: =SUM(B8:P8) -> 0
A9: costilla para parrilla | H9: 137.91 | Q9: =SUM(B9:P9) -> 137.91
A10: filete de res | K10: 29.34 | L10: 35.06 | N10: 29.31 | Q10: =SUM(B10:P10) -> 93.71
A11: rincon | Q11: =SUM(B11:P11) -> 0
A12: lomo | E12: 53.3 | Q12: =SUM(B12:P12) -> 53.3
A13: lengua | Q13: =SUM(B13:P13) -> 0
A14: costilla horno | H14: 137.91 | Q14: =SUM(B14:P14) -> 137.91
A15: bistec picado | E15: 48.17 | Q15: =SUM(B15:P15) -> 48.17
A16: carne guisada | E16: 35.88 | Q16: =SUM(B16:P16) -> 35.88
A17: mondongo | E17: 9.6 | Q17: =SUM(B17:P17) -> 9.6
A18: rabito | Q18: =SUM(B18:P18) -> 0
A19: costilla desayuno | E19: 86.76 | Q19: =SUM(B19:P19) -> 86.76
A20: higado | Q20: =SUM(B20:P20) -> 0
A21: bofe | Q21: =SUM(B21:P21) -> 0
A22: carnes adicionales | E22: =8.73+38.25 -> 46.98 | Q22: =SUM(B22:P22) -> 46.98
A26: 5009 - MARISCOS
A27: filete de pescado | G27: 66 | Q27: =SUM(B27:P27) -> 66
A28: corvina | Q28: =SUM(B28:P28) -> 0
A29: bacalao | Q29: =SUM(B29:P29) -> 0
A30: otros | Q30: =SUM(B30:P30) -> 0
A32: 5010 - POLLO
A33: pollo | E33: 242 | H33: 686.55 | Q33: =SUM(C33:P33) -> 928.55
A34: filete de pechuga parrilla | G34: 42 | Q34: =SUM(B34:P34) -> 42
A35: filete de pechuga criolla | G35: 42 | Q35: =SUM(B35:P35) -> 42
A37: 5011 - VIVERES (MENESTRAS, KETCHUP, OTROS)
A38: porotos | H38: 70 | Q38: =SUM(B38:P38) -> 70
A39: lentejas | H39: 25 | Q39: =SUM(B39:P39) -> 25
A40: chorizo de parrilla | J40: 19 | L40: 17.16 | Q40: =SUM(B40:P40) -> 36.16
A41: chorizo tableño | Q41: =SUM(B41:P41) -> 0
A42: almojabano | Q42: =SUM(B42:P42) -> 0
A43: salchicha para guisar | J43: 28 | Q43: =SUM(B43:P43) -> 28
A44: bollo | G44: 25 | Q44: =SUM(B44:P44) -> 25
A45: carimañola | Q45: =SUM(B45:P45) -> 0
A46: tortilla | G46: =4.77+13 -> 17.77 | Q46: =SUM(B46:P46) -> 17.77
A47: empa | G47: 2.95 | Q47: =SUM(B47:P47) -> 2.95
...

Sheet sem2
A3: PRESUPUESTO Costo de Venta DIC 23
B4: cheque | C4: cheque | D4: cheque | E4: cheque | F4: cheque | G4: cheque | H4: cheque | J4: contado | K4: contado | L4: contado | M4: contado | N4: contado | O4: contado | P4: contado
B5: 45604 | C5: 45605 | D5: 45606 | E5: 45607 | F5: 45608 | G5: 45609 | H5: 45610 | J5: 45604 | K5: 45605 | L5: 45606 | M5: 45607 | N5: 45608 | O5: 45609 | P5: 45610 | Q5: TOTAL
A6: 5008 - CARNES Y PUERCO
A7: chuleta | B7: 249.09 | Q7: =SUM(B7:P7) -> 249.09
A8: churrasco | Q8: =SUM(B8:P8) -> 0
A9: costilla para parrilla | Q9: =SUM(B9:P9) -> 0
A10: filete de res | B10: 24.32 | Q10: =SUM(B10:P10) -> 24.32
A11: rincon | Q11: =SUM(B11:P11) -> 0
A12: lomo | Q12: =SUM(B12:P12) -> 0
A13: lengua | Q13: =SUM(B13:P13) -> 0
A14: costilla horno | Q14: =SUM(B14:P14) -> 0
A15: bistec picado | Q15: =SUM(B15:P15) -> 0
A16: carne guisada | Q16: =SUM(B16:P16) -> 0
A17: mondongo | Q17: =SUM(B17:P17) -> 0
A18: rabito | Q18: =SUM(B18:P18) -> 0
A19: costilla desayuno | Q19: =SUM(B19:P19) -> 0
A20: higado | B20: 41.25 | Q20: =SUM(B20:P20) -> 41.25
A21: bofe | Q21: =SUM(B21:P21) -> 0
A22: carnes adicionales | Q22: =SUM(B22:P22) -> 0
A26: 5009 - MARISCOS
A27: filete de pescado | Q27: =SUM(B27:P27) -> 0
A28: corvina | Q28: =SUM(B28:P28) -> 0
A29: bacalao | Q29: =SUM(B29:P29) -> 0
A30: otros | Q30: =SUM(B30:P30) -> 0
A32: 5010 - POLLO
A33: pollo | Q33: =SUM(B33:P33) -> 0
A34: filete de pechuga parrilla | Q34: =SUM(B34:P34) -> 0
A35: filete de pechuga criolla | Q35: =SUM(B35:P35) -> 0
A37: 5011 - VIVERES (MENESTRAS, KETCHUP, OTROS)
A38: porotos | Q38: =SUM(B38:P38) -> 0
A39: lentejas | Q39: =SUM(B39:P39) -> 0
A40: chorizo de parrilla | B40: 21.45 | Q40: =SUM(B40:P40) -> 21.45
A41: chorizo tableño | Q41: =SUM(B41:P41) -> 0
A42: almojabano | Q42: =SUM(B42:P42) -> 0
A43: salchicha para guisar | B43: 55 | Q43: =SUM(B43:P43) -> 55
A44: bollo | Q44: =SUM(B44:P44) -> 0
A45: carimañola | B45: 8.5 | Q45: =SUM(B45:P45) -> 8.5
A46: tortilla | Q46: =SUM(B46:P46) -> 0
A47: empa | Q47: =SUM(B47:P47) -> 0
...

Sheet sem3
A3: PRESUPUESTO Costo de Venta DIC 23
B4: cheque | C4: cheque | D4: cheque | E4: cheque | F4: cheque | G4: cheque | H4: cheque | J4: contado | K4: contado | L4: contado | M4: contado | N4: contado | O4: contado | P4: contado
B5: 45611 | C5: 45612 | D5: 45613 | E5: 45614 | F5: 45615 | G5: 45616 | H5: 45617 | J5: 45611 | K5: 45612 | L5: 45613 | M5: 45614 | N5: 45615 | O5: 45616 | P5: 45617 | Q5: TOTAL
A6: 5008 - CARNES Y PUERCO
A7: chuleta | Q7: =SUM(B7:P7) -> 0
A8: churrasco | Q8: =SUM(B8:P8) -> 0
A9: costilla para parrilla | Q9: =SUM(B9:P9) -> 0
A10: filete de res | Q10: =SUM(B10:P10) -> 0
A11: rincon | Q11: =SUM(B11:P11) -> 0
A12: lomo | Q12: =SUM(B12:P12) -> 0
A13: lengua | Q13: =SUM(B13:P13) -> 0
A14: costilla horno | Q14: =SUM(B14:P14) -> 0
A15: bistec picado | Q15: =SUM(B15:P15) -> 0
A16: carne guisada | Q16: =SUM(B16:P16) -> 0
A17: mondongo | Q17: =SUM(B17:P17) -> 0
A18: rabito | Q18: =SUM(B18:P18) -> 0
... A22: carnes adicionales | Q22: =SUM(B22:P22) -> 0
A26: 5009 - MARISCOS
A27: filete de pescado | Q27: =SUM(B27:P27) -> 0
A28: corvina | Q28: =SUM(B28:P28) -> 0
A29: bacalao | Q29: =SUM(B29:P29) -> 0
A30: otros | Q30: =SUM(B30:P30) -> 0
A32: 5010 - POLLO
A33: pollo | Q33: =SUM(B33:P33) -> 0
A34: filete de pechuga parrilla | Q34: =SUM(B34:P34) -> 0
A35: filete de pechuga criolla | Q35: =SUM(B35:P35) -> 0
A37: 5011 - VIVERES (MENESTRAS, KETCHUP, OTROS)
A38: porotos | Q38: =SUM(B38:P38) -> 0
A39: lentejas | Q39: =SUM(B39:P39) -> 0
A40: chorizo de parrilla | Q40: =SUM(B40:P40) -> 0
A41: chorizo tableño | Q41: =SUM(B41:P41) -> 0
A42: almojabano | Q42: =SUM(B42:P42) -> 0
A43: salchicha para guisar | Q43: =SUM(B43:P43) -> 0
A44: bollo | Q44: =SUM(B44:P44) -> 0
A45: carimañola | Q45: =SUM(B45:P45) -> 0
A46: tortilla | Q46: =SUM(B46:P46) -> 0
A47: empa | Q47: =SUM(B47:P47) -> 0
Q48: =SUM(D49:P83) -> 0
A49: huevo
A50: mantequilla
...

Sheet sem4
A3: PRESUPUESTO Costo de Venta DIC 23
B4: cheque | C4: cheque | D4: cheque | E4: cheque | F4: cheque | G4: cheque | H4: cheque | J4: contado | K4: contado | L4: contado | M4: contado | N4: contado | O4: contado | P4: contado
B5: 45618 | C5: 45619 | D5: 45620 | E5: 45621 | F5: 45622 | G5: 45623 | H5: 45624 | J5: 45618 | K5: 45619 | L5: 45620 | M5: 45621 | N5: 45622 | O5: 45623 | P5: 45624 | Q5: TOTAL
A6: 5008 - CARNES Y PUERCO
A7: chuleta | Q7: =SUM(B7:P7) -> 0
A8: churrasco | Q8: =SUM(B8:P8) -> 0
A9: costilla para parrilla | Q9: =SUM(B9:P9) -> 0
A10: filete de res | Q10: =SUM(B10:P10) -> 0
A11: rincon | Q11: =SUM(B11:P11) -> 0
A12: lomo | Q12: =SUM(B12:P12) -> 0
A13: lengua | Q13: =SUM(B13:P13) -> 0
A14: costilla horno | Q14: =SUM(B14:P14) -> 0
A15: bistec picado | Q15: =SUM(B15:P15) -> 0
A16: carne guisada | Q16: =SUM(B16:P16) -> 0
A17: mondongo | Q17: =SUM(B17:P17) -> 0
A18: rabito | Q18: =SUM(B18:P18) -> 0
... A22: carnes adicionales | Q22: =SUM(B22:P22) -> 0
A26: 5009 - MARISCOS
A27: filete de pescado | Q27: =SUM(B27:P27) -> 0
A28: corvina | Q28: =SUM(B28:P28) -> 0
A29: bacalao | Q29: =SUM(B29:P29) -> 0
A30: otros | Q30: =SUM(B30:P30) -> 0
A32: 5010 - POLLO
A33: pollo | Q33: =SUM(B33:P33) -> 0
A34: filete de pechuga parrilla | Q34: =SUM(B34:P34) -> 0
A35: filete de pechuga criolla | Q35: =SUM(B35:P35) -> 0
A37: 5011 - VIVERES (MENESTRAS, KETCHUP, OTROS)
A38: porotos | Q38: =SUM(B38:P38) -> 0
A39: lentejas | Q39: =SUM(B39:P39) -> 0
A40: chorizo de parrilla | Q40: =SUM(B40:P40) -> 0
A41: chorizo tableño | Q41: =SUM(B41:P41) -> 0
A42: almojabano | Q42: =SUM(B42:P42) -> 0
A43: salchicha para guisar | Q43: =SUM(B43:P43) -> 0
A44: bollo | Q44: =SUM(B44:P44) -> 0
A45: carimañola | Q45: =SUM(B45:P45) -> 0
A46: tortilla | Q46: =SUM(B46:P46) -> 0
A47: empa | Q47: =SUM(B47:P47) -> 0
Q48: =SUM(D49:P83) -> 0
A49: huevo
A50: mantequilla
...

Sheet Hoja1
B1: 45962 | C1: 45963 | D1: 45964 | E1: 45965 | F1: 45966 | G1: 45967 | H1: 45968 | I1: 45969 | J1: 45970 | K1: 45971
A2: cable telefono internet | G2: 127.88
A3: gasolina | B3: =26+31.65 -> 57.65 | G3: 29.85
A4: dia de teo | C4: 52
A5: dia de leonel | C5: 65
A6: gastos de admins | D6: 13.47
A7: comidas | B7: 64.43
A8: gastos colaboradores | F8: 7.78
A9: horas trabajadas alicia | F9: 44.68
A10: uniformes colabo | G10: 461.17
A11: poliza rest contenido | G11: 107.63
A12: tarjeta de banistmo | E12: 280.46 | H12: 325.17
A13: seguro italo prestamo banistmo | H13: 60.22
A14: seguro italo prestamo CA | H14: 78.53
A15: gastos de pedidos de comidas | G15: 33.88 | H15: 8.8
A16: medicinas | G16: 10.12
A17: cargos bancarios por trans | I17: 104.55
