Workbook

Sheet resultado estimado
A1: PRESUPUESTO ESTADO DE RESULTADO
A2: 2024 mayo
A3: Grupo Pilat, S.A.
B6: 44562 | C6: 44593 | D6: 44621 | E6: 44652 | F6: 44682 | G6: 44713 | H6: 44743 | I6: 44774 | J6: 44805 | K6: Oct-22 | L6: Nov-22 | M6: Dic-22 | N6: COSTOS SEGÚN CANT | O6: PRESUPUESTO SEGÚN CANT ENERO 24 | P6: PROMEDIOS IDEALES DIC
A8: Ingresos | Q8: ACTUAL
A9: 4000 - Ingresos | B9: 27246.28 | C9: 30713.79 | D9: 38889.1 | E9: 34286.15 | F9: 33739.3 | G9: 33369.75 | H9: 33203.71 | I9: 38539.7 | J9: 36930.83 | K9: 45761.68 | L9: 38553.57 | M9: 59145.57 | O9: 50000 | P9: 59000 | Q9: =ventas!G2 -> 10578.4
A10: 4003 - Descuento de jubilados | B10: -1527.1 | C10: -1468.43 | D10: -1692.77 | E10: -1632.95 | F10: -1853.47 | G10: -1958.03 | H10: -1916.18 | I10: -2084.59 | J10: -2131.91 | K10: -2025.79 | L10: -2149.01 | M10: -3011.62 | O10: =U10 -> 3800.1342 | P10: -3011.62 | T10: 45601.61 | U10: =T10/12 -> 3800.1342
A11: Total de Ingresos | B11: =B9+B10 -> 25719.18 | C11: =C9+C10 -> 29245.36 | D11: =D9+D10 -> 37196.33 | E11: =E9+E10 -> 32653.2 | F11: =F9+F10 -> 31885.83 | G11: =G9+G10 -> 31411.72 | H11: =H9+H10 -> 31287.53 | I11: =I9+I10 -> 36455.11 | ... M11: =M9+M10 -> 56133.95 | O11: =O9-O10 -> 46199.866 | P11: =P9+P10 -> 55988.38 | Q11: =Q9-O10 -> 6778.2658
A13: Costo de Venta
A14: 5008 - CARNES Y PUERCO | B14: 2149.55 | C14: 1912.97 | D14: 2763.34 | E14: 2423.23 | F14: 2975.96 | G14: 2898.9 | H14: 2998.34 | I14: 3744.16 | J14: 3631.38 | K14: 5111.8186 | L14: 3642.89 | M14: 4379 | O14: =N15+N16+N17+N18+N21+N22+N23+N24+N25+N26+N27+N29+N30+N31+N32+N33 -> 4565.1796 | P14: 3541.7822
A15: chuleta | N15: =[1]CHULETAS!$C$21 -> 1404.5338
A16: churrasco | N16: =[1]CHURRASCO!$C$21 -> 285.96554
A17: costilla para parrilla | N17: ='[1]COSTILLAS ASADAS'!$C$21 -> 391.36152
A18: filete de res | N18: ='[1]FILETE DE RES '!$C$21 -> 405.24574
A19: rincon
A20: lomo | N20: =[2]LOMO!$C$21 -> 236.51472
A21: lomo | N21: =[2]LOMO!$C$21 -> 236.51472
A22: lengua | N22: =[2]LENGUA!$C$21 -> 184.98887
A23: costilla horno | N23: ='[2]COSTILLA HORNO'!$C$21 -> 390.35299
A24: bistec picado | N24: ='[2]BISTEC PICADO'!$C$21 -> 253.56175
A25: bolita de carne | N25: 55
A26: carne guisada | N26: ='[2]CARNE GUISADA'!$C$21 -> 155.53526
A27: mondongo | N27: =[2]MONDONGO!$C$21 -> 47.804304
A28: rabito
A29: costilla desayuno | N29: ='[3]COSTILLA FRITA'!$C$21 -> 226.64542
A30: bistec cinta | N30: 55
A31: higado | N31: =[3]HIGADO!$C$21 -> 78.967625
A32: carnes imprevistas | N32: 200
A33: bofe | N33: =[3]BOFE!$C$21 -> 193.70203
A35: 5009 - MARISCOS | B35: 243.92 | C35: 35 | D35: 660.61 | E35: 718.71 | F35: 327.19 | G35: 229.55 | H35: 407.15 | I35: 404.81 | J35: 571.52 | K35: 255.26236 | L35: 217.47 | M35: 233.47 | O35: =SUM(N36:N38)+150 -> 635.81056 | P35: 210.16
A36: filete de pescado | N36: ='[2]FILETE DE PESCADO'!$C$21 -> 283.16468
A37: corvina | N37: =[2]CORVINA!$C$22 -> 75.132288
A38: bacalao | N38: =[2]BACALAO!$C$21 -> 127.51358
A40: 5010 - POLLO | B40: 2737.95 | C40: 4080.58 | D40: 4712.83 | E40: 4507.88 | F40: 3669.39 | G40: 3739.36 | H40: 3624.15 | I40: 4356.64 | J40: 4446.79 | K40: 467.17438 | L40: 5278.2 | M40: 5977.99 | O40: =SUM(N41:N43) -> 4323.9313 | P40: 4058.86
A41: pollo | N41: ='[1]POLLO calculo'!$B$18 -> 4131.6058
A42: filete de pechuga parrilla | N42: ='[1]FILETE DE PECHUGA'!$C$22 -> 90.540205
A43: filete de pechuga criolla | N43: ='[2]FILETE PECHUGA '!$C$22 -> 101.78529
A45: 5011 - VIVERES (MENESTRAS, KETCHUP, OTROS) | B45: 3579.56 | C45: 3070.83 | D45: 3453.6 | E45: 1513.71 | F45: 1820.39 | G45: 1993.32 | H45: 3016.66 | I45: 2132.07 | J45: 2803.97 | K45: 4239.0395 | L45: 2920.89 | M45: 3103.51 | O45: =SUM(N46:N56) -> 1564.0177 | P45: 2462.5625
A46: porotos | N46: =[4]ARROZ!$E$21 -> 287.5
A47: lentejas | N47: =[4]ARROZ!$D$21 -> 222.75
...

Sheet Hoja1
C2: ='resultado estimado'!O72 -> 20262.062
B3: Presupuesto según porcentajes ideales | C3: =C2 -> 20262.062
B4: 5008 - CARNES Y PUERCO | C4: =$C$3*D4 -> 3820.2413 | D4: 0.18854158
B5: 5009 - MARISCOS | C5: =$C$3*D5 -> 343.42119 | D5: 0.016948975
B6: 5010 - POLLO | C6: =$C$3*D6 -> 4315.622 | D6: 0.21299027
B7: 5011 - VIVERES (MENESTRAS, KETCHUP, OTROS) | C7: =$C$3*D7 -> 2238.3315 | D7: 0.11046909
B8: 5012 - SODAS, REFRESCOS AGUA | C8: =$C$3*D8 -> 2447.7389 | D8: 0.12080404
B9: 5013 - FIAMBRERAS, ENVASES VARIOS | C9: =$C$3*D9 -> 1236.6238 | D9: 0.061031491
B10: 5014 - ARROZ,LEGUMBRES,PAPITAS, ETC | C10: =$C$3*D10 -> 3283.7836 | D10: 0.16206562
B11: 6101 - GAS | C11: =$C$3*D11 -> 2576.2997 | D11: 0.12714894

Sheet ventas
A1: fecha | B1: ventas efect | C1: ventas yappy | D1: ventas tarjetas | E1: ventas pedidos ya + uber | F1: total
A2: 45597 | B2: 1175.32 | C2: 127.62 | D2: =538.28+144.29+421.24 -> 1103.81 | F2: =SUM(B2:E29) -> 10161.8 | G2: 10578.4
A3: 45598 | B3: 913.26 | C3: 163.22 | D3: =326.25+156.5+464.02 -> 946.77 | G3: =F2-G2 -> -416.6
A4: 45599 | B4: 291.9 | C4: 36.6 | D4: =163.68+47.96+161.6 -> 373.24
A5: 45600 | B5: 403.78 | C5: 24.55 | D5: =217.04+65.99+228.39 -> 511.42
A6: 45601 | B6: 708.28 | C6: 98.32 | D6: =275.4+83.12+259.27 -> 617.79
A7: 45602 | B7: 678.07 | C7: 52.46 | D7: =164.13+16.84+127.72 -> 308.69
A8: 45603 | B8: 882.53 | C8: 78.75 | D8: =335.17+79.76+250.49 -> 665.42
A9: 45604
A10: 45605
A11: 45606
A12: 45607
A13: 45608
A14: 45609
A15: 45610
A16: 45611
A17: 45612
A18: 45613

Sheet ventas real
A1: fecha | B1: ventas efect | C1: ventas yappy | D1: ventas tarjetas | E1: ventas pedidos ya + uber | F1: total
A2: 45597 | B2: 1150.32 | F2: =SUM(B2:E29) -> 9935.53 | G2: =ventas!F2 -> 10161.8
A3: 45598 | B3: 913.26 | G3: =F2-G2 -> -226.27
A4: 45599 | B4: 291.9 | G4: =G3+ventas!G3 -> -642.87
A5: 45600 | B5: 403.78
A6: 45601 | B6: 688.28
A7: 45602 | B7: 648.07
A8: 45603 | B8: 882.53 | C8: 534.78 | D8: 4422.61
A9: 45604
A10: 45605
A11: 45606 | H11: =78.75+52.46+98.32+24.55+36.6+163.22+127.62 -> 581.52
A12: 45607
A13: 45608
A14: 45609
A15: 45610
A16: 45611
A17: 45612
A18: 45613
